Workbook

Sheet Project Data
A1: Project Name | B1: Route planning App
A3: Online team meeting | B3: https://tu-berlin.zoom-x.de/j/63201367987?pwd=pwLP7eO90NCqkHyHE0cssfqZA0PwDl.1
A5: Production system (if any)
A6: Test system (if any) | B6: ...
A8: GitHub repository | B8: https://github.com/amosproj/amos2025ss03-route-planning-app
A9: GitHub feature board | B9: https://github.com/orgs/amosproj/projects/81
A10: GitHub imp-squared backlog | B10: https://github.com/orgs/amosproj/projects/85
A12: Team T-shirt (white) | B12: https://www.shirtinator.de/loadBasket/PNnhXl2COPF
A13: Team T-shirt (black) | B13: ...
A15: Additional materials | B15: ...
A17: Team maling list | B17: oss-amos-proj3@lists.fau.de

Sheet Project Team
A1: Last Name | B1: First Name | C1: GitHub User Name | D1: Email Address
A2: Sandt | B2: Eloi | C2: eloinoel | D2: eloi.sandt@campus.tu-berlin.de
A3: Justus | B3: Kleinau | C3: jkleinau | D3: j.kleinau@campus.tu-berlin.de
A4: Harms | B4: Finn | C4: innif
A5: Karkani | B5: Despoina | C5: dkarkani | D5: despoina.karkani@campus.tu-berlin.de
A6: Karmokar | B6: Subroto | C6: SK-Subroto | D6: subroto.karmokar@fau.de
A7: Dutta | B7: Arkadeep | C7: arkadeepberlin | D7: arkadeep.dutta@campus.tu-berlin.de
A8: Uddin | B8: Md Fahim | C8: fahimu10 | D8: fahim.uddin@fau.de
A9: Khanam | B9: Faria Rahman | C9: fariarahman15 | D9: faria.khanam@fau.de
A10: Summerer | B10: Felix | C10: SUFelix | D10: felix.summerer@fau.de

Sheet Role Assignments
C1: Product Owner
A2: # | B2: Meeting Day | C2: Review | D2: Planning | E2: Software Developer | F2: Release Manager | G2: Scrum Master | H2: Comment
A3: 1 | B3: 45763 | D3: Despina | E3: Everyone else | F3: N/A | G3: Eloi
A4: 2 | B4: =B3+7 -> 45770 | C4: Despina | D4: Arkadeep | E4: Everyone else | F4: Finn | G4: Eloi
A5: 3 | B5: =B4+7 -> 45777 | C5: Arkadeep | D5: Despina | E5: Everyone else | F5: Justus | G5: Eloi
A6: 4 | B6: =B5+7 -> 45784 | C6: Despina | D6: Arkadeep | E6: Everyone else | F6: Faria | G6: Eloi
A7: 5 | B7: =B6+7 -> 45791 | C7: Arkadeep | D7: Despina | E7: Everyone else | F7: Subroto | G7: Eloi
A8: 6 | B8: =B7+7 -> 45798 | C8: Despina | D8: Arkadeep | F8: Felix | G8: Eloi
A9: 7 | B9: =B8+7 -> 45805 | C9: Arkadeep | D9: Despina | F9: Fahim | G9: Eloi | H9: Mid-term due
A10: 8 | B10: =B9+7 -> 45812 | C10: Despina | D10: Arkadeep | F10: Subroto | G10: Eloi
A11: 9 | B11: =B10+7 -> 45819 | C11: Arkadeep | D11: Despina | F11: Faria | G11: Eloi
A12: 10 | B12: 45819 | C12: Despina | D12: Arkadeep | F12: Justus | G12: Eloi
A13: 11 | B13: =B12+7 -> 45826 | C13: Arkadeep | D13: Despina | F13: Felix | G13: Eloi
A14: 12 | B14: =B13+7 -> 45833 | C14: Despina | D14: Arkadeep | F14: Fahim | G14: Eloi
A15: 13 | B15: =B14+7 -> 45840 | C15: Arkadeep | D15: Despina | F15: Subroto | G15: Eloi
A16: 14 | B16: =B15+7 -> 45847 | C16: Despina | D16: Arkadeep | F16: Faria | G16: Eloi | H16: Demo day!
A17: 15 | B17: =B16+7 -> 45854 | C17: Arkadeep | G17: Eloi | H17: Retrospective
A19: Product owners, software developers, and Scurm Master are set and ideally don't change over time; the critical part is the Release Manager role you need to define here

Sheet Team Contract
A1: Goals | B1: Have an enjoyable experience in working together
B2: learn from each other
B3: Our teams tries to create tangible progress with the application every week
B4: Complete ECTS and get good grade
B5: Provide a usefull solution to meisterwerk
A7: Meeting norms | B7: All team-meetings are mandatory unless a valid reason is communicated in advance
B8: be on time to value each other's time
B9: Ask questions if your are not clear on something.
B10: The meeting starts on time, even if not all members are present yet
B11: Camera On :)
A13: Working norms | B13: Team members should be open to feedback and view it as a growth opportunity
B14: We use feature, development and fix-branches in git
B15: When we face problems or fail to reach our goals, we should communicate that as soon as possible
B16: Always help each other!
B17: agree on who does what and keep track of it
B18: Follow coding conventions
B19: Openly communicate working capacity, so work can be attributed accordingly
B20: Keep each other updated about progress
A22: Coordination norms | B22: The Product owners for Review and Planning respectively switch every week
B23: The PO's (at least, devs are always welcome to join) meet with the industry partner at regular intervals and communicate feature requests to the rest of the team
B24: When facing decisions that cant be resolved in a discussion, we put it to vote
B25: keep essential information and links to tools centralised in one place (seperate discord channel)
A27: Communication norms | B27: Use the communication tools that we have. In our case a Discord Server
B28: We should answer within one day
B29: There are no stupid questions!
B30: Communicate respectfully and let everybody speak out
B31: Respect each others opinions, we are all here to learn :)
B32: constructive criticism, talk about solutions
B33: communicate illnesses and expected work downtime and what it means for others
B34: Smaller problems with persons in thew group should be voiced in meetings, larger concerns should be discussed in a one-on-one call first
A36: Consideration norms | B36: Each task will have a primary owner(s) and a reviewer to ensure accountability and quality.
B37: Talk about the problem, talk with the roles, get the context. Communication is very important to understand everything
B38: prefer to speak in public over speaking privately?
A40: Cont. improvement norms | B40: Keep 15 minutes atleast for Sprint retrospective
B41: Give constructive feedback on Pull Requests
A43: Rewards
B44: One evening/afternoon/whatever of fun online games
A46: Sanctions
B47: 10 minutes of mandatory guided meditation… with a goat yoga video soundtrack
B48: A silly video-filter has to be activated for the next meeting
...

Sheet Product Goal
A1: Product Vision | B1: Project Mission
A3: To build an intelligent, automated route optimization tool that empowers organizations to efficiently assign appointments to field workers—optimizing for time, cost, and resource usage—while maximizing overall operational efficiency and service quality | B3: The mission of this project is to create an MVP for the AMOS Route Optimizer. Core functionality will include uploading appointment data, generating an optimized route plan based on efficiency criteria (e.g., time, cost, resource usage), and displaying the resulting plan on an interactive map interface.

Sheet Product Glossary
A1: Term | B1: Definition
A2: MVP | B2: Minimum Viable Product
A3: Route Optimizer | B3: Leanest Rute based on different parameters

Sheet Sprint Goals
A1: Sprint # | B1: Sprint goal
A2: 1 | B2: None
A3: =A2+1 -> 2 | B3: None
A4: =A3+1 -> 3 | B4: None
A5: =A4+1 -> 4 | B5: None
A6: =A5+1 -> 5 | B6: Finalize the optimization trigger flow, integrate distance calculations, and implement preprocessing to detect potential solver issues before execution.
A7: =A6+1 -> 6 | B7: Connect backend route data to the frontend, visualize the full daily and worker plans, and introduce servicetime customization in both backend and UI.
A8: =A7+1 -> 7 | B8: Enhance route planning by adding time constraints, optimizing performance for large datasets, and improving scheduling accuracy and scalability.
A9: =A8+1 -> 8 | B9: Extend backend capabilities with support for skills, time windows, and caching, while enabling multi-day optimization and custom configuration options in the frontend.
A10: =A9+1 -> 9 | B10: Enhance optimization flexibility by introducing new cost parameters, improving user control over addresses and day selection, and ensuring intuitive navigation between calendar and map views.
A11: =A10+1 -> 10 | B11: Empower users to tailor the optimization to their needs by exposing additional configuration parameters enabling greater control, flexibility, and relevance of route planning for real-world scenarios
A12: =A11+1 -> 11 | B12: Improve optimization fairness and robustness, finalize documentation, and enhance the frontend experience through bug fixes and UI improvements.
A13: =A12+1 -> 12
A14: =A13+1 -> 13
A15: =A14+1 -> 14
A16: =A15+1 -> 15

Sheet Velocity Tracking
A1: Sprint # | B1: Story Points Realized | C1: Average
A2: 1
A3: =A2+1 -> 2 | B3: =SUM('Mid-Project Release plan'!F25:F28) -> 11
A4: =A3+1 -> 3 | B4: =SUM('Mid-Project Release plan'!F30:F41) -> 39
A5: =A4+1 -> 4 | B5: =SUM('Mid-Project Release plan'!F42:F49) -> 37
A6: =A5+1 -> 5 | B6: =SUM('Mid-Project Release plan'!F50:F54) -> 37
A7: =A6+1 -> 6 | B7: =SUM('Mid-Project Release plan'!F55:F66) -> 57
A8: =A7+1 -> 7 | B8: =SUM('Final Project Release plan'!F20:F28) -> 44
A9: =A8+1 -> 8 | B9: 34
A10: =A9+1 -> 9 | B10: =SUM('Final Project Release plan'!F38:F45) -> 32
A11: =A10+1 -> 10
A12: =A11+1 -> 11
A13: =A12+1 -> 12
A14: =A13+1 -> 13
A15: =A14+1 -> 14
A16: =A15+1 -> 15
A17: Average | C17: =AVERAGE(B2:B9) -> 37
B18: PLEASE CREATE THE VELOCITY CHART ON A NEW TAB USING THE DATA FROM THIS TAB

Sheet Velocity Chart

Sheet Mid-Project Release plan
A1: Sprint | B1: Goal | C1: Feature Name | D1: Est. size | E1: Est. remaining | F1: Real size | G1: Real remaining
A3: Release
A5: Total | D5: =sum(D8:D16) -> 170 | E5: =D5 -> 170
A7: Sprint
E8: Estimated burn-down | G8: Real burn-down
A9: 1 | B9: Basic formal documentation requirements | D9: =sum(D19:D24) -> 0 | E9: =$D$5 -> 170 | F9: =sum(F19:F24) -> 0 | G9: =$D$5 -> 170
A10: =A9+1 -> 2 | B10: Set up backend, frontend, and upload infrastructure to support the route planning flow. | D10: =sum(D25:D29) -> 14 | E10: =E9-D9 -> 170 | F10: =sum(F25:F29) -> 11 | G10: =G9-F9 -> 170
A11: =A10+1 -> 3 | B11: Complete the foundation for file upload, schema validation, and routing structure on both backend and frontend to prepare for full route processing. | D11: =sum(D30:D41) -> 44 | E11: =E10-D10 -> 156 | F11: =sum(F30:F41) -> 39 | G11: =G10-F10 -> 159
A12: 4 | B12: Integrate and run the initial optimization plan, connect validated input data, and prepare the frontend for dynamic interaction with editable and visual route elements. | D12: =sum(D42:D49) -> 33 | E12: =E11-D11 -> 112 | F12: =sum(F42:F49) -> 37 | G12: =G11-F11 -> 120
A13: 5 | B13: Finalize the optimization trigger flow, integrate distance calculations, and implement preprocessing to detect potential solver issues before execution. | D13: =sum(D50:D54) -> 29 | E13: =E12-D12 -> 79 | F13: =sum(F50:F54) -> 37 | G13: =G12-F12 -> 83
A14: 6 | B14: Connect backend route data to the frontend, visualize the full daily and worker plans, and introduce servicetime customization in both backend and UI. | D14: =sum(D55:D65) -> 50 | E14: =E13-D13 -> 50 | F14: =sum(F56:F59) -> 29 | G14: =G13-F13 -> 46
A15: 7 | B15: To strengthen the core data integrity and reporting capabilities by fully mapping vehicle identifiers, surfacing scheduling exceptions, and delivering precise route metrics—laying the foundation for reliable operations and stakeholder visibility.
A17: Features
A19: =A9 -> 1 | B19: Basic formal documentation requirements | C19: None
A25: =A10 -> 2 | B25: Set up backend, frontend, and upload infrastructure to support the route planning flow. | C25: Set up Backend | D25: 2 | F25: 3
C26: Save & Load Scenarios from JSON | D26: 5 | F26: 3
C27: Set Up CI/CD Pipeline | D27: 5 | F27: 3
C28: Set up Front End | D28: 2 | F28: 2
A30: =A11 -> 3 | B30: Complete the foundation for file upload, schema validation, and routing structure on both backend and frontend to prepare for full route processing. | C30: Agreement on basic structure – Frontend Backend | D30: 8 | F30: 8
C31: Validate Addresses via Google Maps Geocoding API | D31: 8 | F31: 5
C32: Implement Start and Finish Address Fields (Business data) | D32: 1 | F32: 1
C33: Add Worker Count Slider Component | D33: 1 | F33: 1
C34: Create “Start Optimization” Button | D34: 1 | F34: 1
C35: Create a routing structure on the frontend | D35: 3 | F35: 3
C36: Build File Upload Component | D36: 3 | F36: 3
C37: Docker File Creation | D37: 3 | F37: 3
C38: Excel File Upload Functionality | D38: 3 | F38: 3
C39: Convert Uploaded Excel File to JSON | D39: 5 | F39: 3
C40: JSON Schema Validation for Uploaded File | D40: 3 | F40: 3
C41: Create distance matrix from the uploaded address | D41: 5 | F41: 5
A42: 4 | B42: Integrate and run the initial optimization plan, connect validated input data, and prepare the frontend for dynamic interaction with editable and visual route elements. | C42: Migrate Frontend Components to ShadcnUI and TailwindCSS | D42: 2 | F42: 3
C43: Map Business Data Sheet and Appointment Data to the UI | D43: 3 | F43: 5
C44: Move Editable Inputs and Start Button to Map View | D44: 3 | F44: 3
C45: Implement Basic Optimization Plan: First Draft | D45: 8 | F45: 8
C46: Connecting Worker Address Validation and Distance Matrix | D46: 3 | F46: 3
C47: Implement Basic Map View with Location Points Only | D47: 8 | F47: 8
C48: Add Calendar View with Daily Appointment Overview | D48: 3 | F48: 5
C49: Explore Options for Handling Faulty Addresses from Uploaded Files in the UI | D49: 3 | F49: 2
A50: 5 | B50: Finalize the optimization trigger flow, integrate distance calculations, and implement preprocessing to detect potential solver issues before execution. | C50: Implement Preprocessing Logic to Detect Potential Solver Failures: First Draft | D50: 5 | F50: 5
C51: Implement Distance Calculation in the Route Optimization | D51: 3 | F51: 3
...

Sheet Final Project Release plan
A1: Exclude portion of waiting time from cost to accomodate breaks --> possible ghost appointments for breaks | B1: Goal | C1: Feature Name | D1: Est. size | E1: Est. remaining | F1: Real size | G1: Real remaining
A3: Release
A5: Total | D5: =sum(D8:D16) -> 151 | E5: =D5 -> 151
A7: Sprint
E8: Estimated burn-down | G8: Real burn-down
D9: 0 | E9: =$D$5 -> 151 | F9: 0 | G9: =$D$5 -> 151
A10: 7 | B10: Enhance route planning by adding time constraints, optimizing performance for large datasets, and improving scheduling accuracy and scalability. | D10: =sum(D20:D28) -> 42 | E10: =E9-D9 -> 151 | F10: =sum(F20:F28) -> 44 | G10: =G9-F9 -> 151
A11: 8 | B11: To strengthen the core data integrity and reporting capabilities by fully mapping vehicle identifiers, surfacing scheduling exceptions, and delivering precise route metrics—laying the foundation for reliable operations and stakeholder visibility. | D11: =sum(D30:D36) -> 26 | E11: =E10-D10 -> 109 | F11: =sum(F30:F36) -> 34 | G11: =G10-F10 -> 107
A12: 9 | B12: Integrate and run the initial optimization plan, connect validated input data, and prepare the frontend for dynamic interaction with editable and visual route elements. | D12: =sum(D36:D47) -> 41 | E12: =E11-D11 -> 83 | F12: =sum(F37:F47) -> 32 | G12: =G11-F11 -> 73
A13: 10 | B13: Enhance optimization flexibility by introducing new cost parameters, improving user control over addresses and day selection, and ensuring intuitive navigation between calendar and map views. | D13: =sum(D47:D55) -> 42 | E13: =E12-D12 -> 42 | F13: =sum(F47:F55) -> 0 | G13: =G12-F12 -> 41
A14: 11 | B14: Improve optimization fairness and robustness, finalize documentation, and enhance the frontend experience through bug fixes and UI improvements.
E19: Estimated burn-down | G19: Real burn-down
A20: 7 | B20: Enhance route planning by adding time constraints, optimizing performance for large datasets, and improving scheduling accuracy and scalability. | C20: Create Company Info Configuration page | D20: 8 | F20: 8
C21: Scipt for Dummy Tets Creation | D21: 5 | F21: 5
C22: Add Colored Start and end Address | D22: 3 | F22: 3
C23: Add Month Support to calendar View | D23: 5 | F23: 8
C24: Add Button to Daily and OWrker Plan | D24: 2 | F24: 2
C25: Calculate Waiting time in Post processing | D25: 5 | F25: 5
C26: Separate Pages for daily and Individual WOrker Plan | D26: 8 | F26: 8
C27: Figure Starting Time Interval | D27: 3 | F27: 2
C28: Add Route Metrics to Data Structure | D28: 3 | F28: 3
A30: 8 | B30: To strengthen the core data integrity and reporting capabilities by fully mapping vehicle identifiers, surfacing scheduling exceptions, and delivering precise route metrics—laying the foundation for reliable operations and stakeholder visibility. | C30: Map Veihicle Ids to Output | D30: 3 | F30: 3
C31: Rewrite Route Metrics Calculation to Be Accurate and Integrated | D31: 3 | F31: 3
C32: Implement Logic for Multiple Depots in the Solver | D32: 5 | F32: 13
C33: Show Map view redirect | D33: 2 | F33: 2
C34: Implement caching | D34: 8 | F34: 8
C35: Add more parameters to configuration page | D35: 5 | F35: 5
A37: 9 | B37: Enhance optimization flexibility by introducing new cost parameters, improving user control over addresses and day selection, and ensuring intuitive navigation between calendar and map views.
C38: Include Depot Departure/Return Time in Validation Report | D38: 3 | F38: 3
C39: Show Optimization details on Multi day selection page | D39: 8 | F39: 8
C40: Back Button in Map View Details to Current Month | D40: 2 | F40: 2
C41: Update Save Button in Company Configuration Page | D41: 2 | F41: 2
C42: Integrate Metric Logic into Solver | D42: 5 | F42: 5
C43: Add Cost Metrics to Data Structure | D43: 3 | F43: 2
C44: Add Option to Exclude Vehicles | D44: 5 | F44: 5
C45: Enhance Multi-Day Selection feature | D45: 5 | F45: 5
A47: 10 | B47: Enhance optimization flexibility by introducing new cost parameters, improving user control over addresses and day selection, and ensuring intuitive navigation between calendar and map views. | C47: Exclude portion of waiting time from cost to accomodate breaks --> possible ghost appointments for breaks | D47: 8
C48: Lunch Break UI Handling | D48: 5
C49: Distinguish Between Appointments and Depots in Validation Report | D49: 3
C50: Fixing the Validation report | D50: 5
...

Sheet Burndown Chart

Sheet Definition of Done
A1: # | B1: Feature Definition of Done | C1: Sprint Release Definition of Done | D1: Project Release Definition of Done
B3: Frontend and backend components for the feature are implemented and integrated Feature is reviewed via code review (e.g., pull request approved) Feature is merged into the development branch without breaking other functionalities The feature is demo-ready and accepted by the Product Owner | C3: The app builds and runs successfully in a clean environment All sprint backlog items marked as "Done" meet the Feature DoD Demo conducted with functioning features shown via "show and tell" in Sprint Planning session by the developers Release notes are created and shared (e.g., summary in planning document or GitHub) Velocity is tracked and recorded | D3: All core MVP functionality is implemented and passes acceptance tests Optimized route output is visualized on the map using real user inputs Documentation is complete (README.md, user guide, build instructions) System passes testing across common browsers/environments Mid- and final release plans are fulfilled Build process video and required deliverables are uploaded

Sheet Documentation
A1: Type | B1: Link / reference

Sheet Bill of Materials
A1: # | B1: Context | C1: Name | D1: Version | E1: License | F1: Comment
B2: Programming Language for Backend | C2: Python | D2: 3.11 | E2: Python Software Foundation (PSF) License
B3: API Framework for Backend API | C3: FastAPI | D3: 0.103.1 | E3: MIT License
B4: Route Optimization in Backend | C4: Google OR | D4: 9.7 | E4: Apache 2.0
B5: Get Distance-Matrix between points for routing | C5: Google Maps API | D5: N/A | E5: Commercial
B6: Programming Language for Frontend | C6: Typescript | D6: 5.7.2 | E6: Apache 2.0
B7: Framework for Frontend | C7: ReactJS | D7: 19.01 | E7: MIT License
B8: UI-Components for Frontend | C8: Shadcm UI | D8: 2.5.0 | E8: MIT License
B9: CSS Framwork for Frontend | C9: TailwindCSS | D9: 4 | E9: MIT License

Sheet Planning Poker
A1: ='Project Team'!A1 -> Last Name | B1: ='Project Team'!B1 -> First Name | C1: Value
A2: ='Project Team'!A1 -> Last Name | B2: =#REF! -> #REF! | E2: =average(C2:C10) -> #DIV/0! | F2: =if(stdev(C2:C7) > 0,"NOK", "OK") -> #DIV/0!
A3: =#REF! -> #REF! | B3: =#REF! -> #REF!
A4: ='Project Team'!A3 -> Justus | B4: ='Project Team'!B3 -> Kleinau
A5: =#REF! -> #REF! | B5: =#REF! -> #REF!
A6: ='Project Team'!A4 -> Harms | B6: ='Project Team'!B4 -> Finn | E6: 0 | F6: No size
A7: ='Project Team'!A5 -> Karkani | B7: ='Project Team'!B5 -> Despoina | E7: 1 | F7: Trivial size
A8: ='Project Team'!A6 -> Karmokar | B8: ='Project Team'!B6 -> Subroto | E8: 2 | F8: Small size
A9: ='Project Team'!A8 -> Uddin | B9: ='Project Team'!B8 -> Md Fahim | E9: 3 | F9: Medium size
A10: ='Project Team'!A9 -> Khanam | B10: ='Project Team'!B9 -> Faria Rahman | E10: 5 | F10: Large size
A11: Summerer | B11: Felix | E11: 8 | F11: Very large size
E12: 13 | F12: Too large (size)
A14: How to play planning poker
A16: 1. Everyone type their number into their value field, don't hit return yet
A17: 2. Someone, perhaps a product owner, count down 3.. 2.. 1..
A18: 3. Then, everyone hit return to submit their value
